[2025-01-06T14:27:59.867+0000] {local_task_job_runner.py:123} INFO - ::group::Pre task execution logs
[2025-01-06T14:27:59.874+0000] {taskinstance.py:2613} INFO - Dependencies all met for dep_context=non-requeueable deps ti=<TaskInstance: transfer.transfer_Users manual__2025-01-06T14:27:59.427301+00:00 [queued]>
[2025-01-06T14:27:59.877+0000] {taskinstance.py:2613} INFO - Dependencies all met for dep_context=requeueable deps ti=<TaskInstance: transfer.transfer_Users manual__2025-01-06T14:27:59.427301+00:00 [queued]>
[2025-01-06T14:27:59.877+0000] {taskinstance.py:2866} INFO - Starting attempt 1 of 1
[2025-01-06T14:27:59.881+0000] {taskinstance.py:2889} INFO - Executing <Task(GenericTransfer): transfer_Users> on 2025-01-06 14:27:59.427301+00:00
[2025-01-06T14:27:59.883+0000] {warnings.py:112} WARNING - /home/***/.local/lib/python3.12/site-packages/***/task/task_runner/standard_task_runner.py:70: DeprecationWarning: This process (pid=86) is multi-threaded, use of fork() may lead to deadlocks in the child.
  pid = os.fork()

[2025-01-06T14:27:59.884+0000] {standard_task_runner.py:72} INFO - Started process 87 to run task
[2025-01-06T14:27:59.884+0000] {standard_task_runner.py:104} INFO - Running: ['***', 'tasks', 'run', 'transfer', 'transfer_Users', 'manual__2025-01-06T14:27:59.427301+00:00', '--job-id', '12', '--raw', '--subdir', 'DAGS_FOLDER/tranfer_dag.py', '--cfg-path', '/tmp/tmpcpsvqr8j']
[2025-01-06T14:27:59.885+0000] {standard_task_runner.py:105} INFO - Job 12: Subtask transfer_Users
[2025-01-06T14:27:59.902+0000] {task_command.py:467} INFO - Running <TaskInstance: transfer.transfer_Users manual__2025-01-06T14:27:59.427301+00:00 [running]> on host 78501d4f6bfb
[2025-01-06T14:27:59.930+0000] {taskinstance.py:3132} INFO - Exporting env vars: AIRFLOW_CTX_DAG_OWNER='***' AIRFLOW_CTX_DAG_ID='transfer' AIRFLOW_CTX_TASK_ID='transfer_Users' AIRFLOW_CTX_EXECUTION_DATE='2025-01-06T14:27:59.427301+00:00' AIRFLOW_CTX_TRY_NUMBER='1' AIRFLOW_CTX_DAG_RUN_ID='manual__2025-01-06T14:27:59.427301+00:00'
[2025-01-06T14:27:59.931+0000] {taskinstance.py:731} INFO - ::endgroup::
[2025-01-06T14:27:59.939+0000] {base.py:84} INFO - Retrieving connection 'postgres-source'
[2025-01-06T14:27:59.950+0000] {base.py:84} INFO - Retrieving connection 'mysql-target'
[2025-01-06T14:27:59.951+0000] {generic_transfer.py:79} INFO - Extracting data from postgres-source
[2025-01-06T14:27:59.951+0000] {generic_transfer.py:80} INFO - Executing: 
 SELECT * FROM Users
[2025-01-06T14:27:59.954+0000] {base.py:84} INFO - Retrieving connection 'postgres-source'
[2025-01-06T14:27:59.956+0000] {sql.py:553} INFO - Running statement: SELECT * FROM Users, parameters: None
[2025-01-06T14:27:59.957+0000] {sql.py:562} INFO - Rows affected: 2
[2025-01-06T14:27:59.957+0000] {generic_transfer.py:107} INFO - Inserting rows into mysql-target
[2025-01-06T14:27:59.960+0000] {base.py:84} INFO - Retrieving connection 'mysql-target'
[2025-01-06T14:27:59.964+0000] {taskinstance.py:3311} ERROR - Task failed with exception
Traceback (most recent call last):
  File "/home/airflow/.local/lib/python3.12/site-packages/airflow/models/taskinstance.py", line 767, in _execute_task
    result = _execute_callable(context=context, **execute_callable_kwargs)
             ^^^^^^^^^^^^^^^^^^^^^^^^^^^^^^^^^^^^^^^^^^^^^^^^^^^^^^^^^^^^^
  File "/home/airflow/.local/lib/python3.12/site-packages/airflow/models/taskinstance.py", line 733, in _execute_callable
    return ExecutionCallableRunner(
           ^^^^^^^^^^^^^^^^^^^^^^^^
  File "/home/airflow/.local/lib/python3.12/site-packages/airflow/utils/operator_helpers.py", line 252, in run
    return self.func(*args, **kwargs)
           ^^^^^^^^^^^^^^^^^^^^^^^^^^
  File "/home/airflow/.local/lib/python3.12/site-packages/airflow/models/baseoperator.py", line 422, in wrapper
    return func(self, *args, **kwargs)
           ^^^^^^^^^^^^^^^^^^^^^^^^^^^
  File "/home/airflow/.local/lib/python3.12/site-packages/airflow/operators/generic_transfer.py", line 108, in execute
    insert_rows(table=self.destination_table, rows=results, **self.insert_args)
  File "/home/airflow/.local/lib/python3.12/site-packages/airflow/providers/common/sql/hooks/sql.py", line 688, in insert_rows
    cur.execute(sql, values)
  File "/home/airflow/.local/lib/python3.12/site-packages/MySQLdb/cursors.py", line 179, in execute
    res = self._query(mogrified_query)
          ^^^^^^^^^^^^^^^^^^^^^^^^^^^^
  File "/home/airflow/.local/lib/python3.12/site-packages/MySQLdb/cursors.py", line 330, in _query
    db.query(q)
  File "/home/airflow/.local/lib/python3.12/site-packages/MySQLdb/connections.py", line 265, in query
    _mysql.connection.query(self, query)
MySQLdb.ProgrammingError: (1146, "Table 'db.Users' doesn't exist")
[2025-01-06T14:27:59.968+0000] {taskinstance.py:1225} INFO - Marking task as FAILED. dag_id=transfer, task_id=transfer_Users, run_id=manual__2025-01-06T14:27:59.427301+00:00, execution_date=20250106T142759, start_date=20250106T142759, end_date=20250106T142759
[2025-01-06T14:27:59.972+0000] {taskinstance.py:340} INFO - ::group::Post task execution logs
[2025-01-06T14:27:59.972+0000] {standard_task_runner.py:124} ERROR - Failed to execute job 12 for task transfer_Users ((1146, "Table 'db.Users' doesn't exist"); 87)
Traceback (most recent call last):
  File "/home/airflow/.local/lib/python3.12/site-packages/airflow/task/task_runner/standard_task_runner.py", line 117, in _start_by_fork
    ret = args.func(args, dag=self.dag)
          ^^^^^^^^^^^^^^^^^^^^^^^^^^^^^
  File "/home/airflow/.local/lib/python3.12/site-packages/airflow/cli/cli_config.py", line 49, in command
    return func(*args, **kwargs)
           ^^^^^^^^^^^^^^^^^^^^^
  File "/home/airflow/.local/lib/python3.12/site-packages/airflow/utils/cli.py", line 116, in wrapper
    return f(*args, **kwargs)
           ^^^^^^^^^^^^^^^^^^
  File "/home/airflow/.local/lib/python3.12/site-packages/airflow/cli/commands/task_command.py", line 483, in task_run
    task_return_code = _run_task_by_selected_method(args, _dag, ti)
                       ^^^^^^^^^^^^^^^^^^^^^^^^^^^^^^^^^^^^^^^^^^^^
  File "/home/airflow/.local/lib/python3.12/site-packages/airflow/cli/commands/task_command.py", line 256, in _run_task_by_selected_method
    return _run_raw_task(args, ti)
           ^^^^^^^^^^^^^^^^^^^^^^^
  File "/home/airflow/.local/lib/python3.12/site-packages/airflow/cli/commands/task_command.py", line 341, in _run_raw_task
    return ti._run_raw_task(
           ^^^^^^^^^^^^^^^^^
  File "/home/airflow/.local/lib/python3.12/site-packages/airflow/utils/session.py", line 97, in wrapper
    return func(*args, session=session, **kwargs)
           ^^^^^^^^^^^^^^^^^^^^^^^^^^^^^^^^^^^^^^
  File "/home/airflow/.local/lib/python3.12/site-packages/airflow/models/taskinstance.py", line 3005, in _run_raw_task
    return _run_raw_task(
           ^^^^^^^^^^^^^^
  File "/home/airflow/.local/lib/python3.12/site-packages/airflow/models/taskinstance.py", line 273, in _run_raw_task
    TaskInstance._execute_task_with_callbacks(
  File "/home/airflow/.local/lib/python3.12/site-packages/airflow/models/taskinstance.py", line 3159, in _execute_task_with_callbacks
    result = self._execute_task(context, task_orig)
             ^^^^^^^^^^^^^^^^^^^^^^^^^^^^^^^^^^^^^^
  File "/home/airflow/.local/lib/python3.12/site-packages/airflow/models/taskinstance.py", line 3183, in _execute_task
    return _execute_task(self, context, task_orig)
           ^^^^^^^^^^^^^^^^^^^^^^^^^^^^^^^^^^^^^^^
  File "/home/airflow/.local/lib/python3.12/site-packages/airflow/models/taskinstance.py", line 767, in _execute_task
    result = _execute_callable(context=context, **execute_callable_kwargs)
             ^^^^^^^^^^^^^^^^^^^^^^^^^^^^^^^^^^^^^^^^^^^^^^^^^^^^^^^^^^^^^
  File "/home/airflow/.local/lib/python3.12/site-packages/airflow/models/taskinstance.py", line 733, in _execute_callable
    return ExecutionCallableRunner(
           ^^^^^^^^^^^^^^^^^^^^^^^^
  File "/home/airflow/.local/lib/python3.12/site-packages/airflow/utils/operator_helpers.py", line 252, in run
    return self.func(*args, **kwargs)
           ^^^^^^^^^^^^^^^^^^^^^^^^^^
  File "/home/airflow/.local/lib/python3.12/site-packages/airflow/models/baseoperator.py", line 422, in wrapper
    return func(self, *args, **kwargs)
           ^^^^^^^^^^^^^^^^^^^^^^^^^^^
  File "/home/airflow/.local/lib/python3.12/site-packages/airflow/operators/generic_transfer.py", line 108, in execute
    insert_rows(table=self.destination_table, rows=results, **self.insert_args)
  File "/home/airflow/.local/lib/python3.12/site-packages/airflow/providers/common/sql/hooks/sql.py", line 688, in insert_rows
    cur.execute(sql, values)
  File "/home/airflow/.local/lib/python3.12/site-packages/MySQLdb/cursors.py", line 179, in execute
    res = self._query(mogrified_query)
          ^^^^^^^^^^^^^^^^^^^^^^^^^^^^
  File "/home/airflow/.local/lib/python3.12/site-packages/MySQLdb/cursors.py", line 330, in _query
    db.query(q)
  File "/home/airflow/.local/lib/python3.12/site-packages/MySQLdb/connections.py", line 265, in query
    _mysql.connection.query(self, query)
MySQLdb.ProgrammingError: (1146, "Table 'db.Users' doesn't exist")
[2025-01-06T14:27:59.980+0000] {local_task_job_runner.py:266} INFO - Task exited with return code 1
[2025-01-06T14:27:59.986+0000] {taskinstance.py:3895} INFO - 0 downstream tasks scheduled from follow-on schedule check
[2025-01-06T14:27:59.987+0000] {local_task_job_runner.py:245} INFO - ::endgroup::
